test_factorial (__main__.TestExercice) ... ERROR
test_prefixes (__main__.TestExercice) ... ok
test_summation (__main__.TestExercice) ... ok

======================================================================
ERROR: test_factorial (__main__.TestExercice)
----------------------------------------------------------------------
Traceback (most recent call last):
  File "test_exercice.py", line 44, in test_factorial
    output = [exercice.factorial(v) for v in values]
  File "test_exercice.py", line 44, in <listcomp>
    output = [exercice.factorial(v) for v in values]
  File "/home/runner/work/c01_ch5_exercices-helobrouillette/c01_ch5_exercices-helobrouillette/exercice.py", line 38, in factorial
    return math.factorial(number)
NameError: name 'math' is not defined

----------------------------------------------------------------------
Ran 3 tests in 0.001s

FAILED (errors=1)
